Traceback (most recent call last):
  File "C:\Users\Tomas\anaconda3.1\envs\test\lib\site-packages\jupyter_cache\executors\utils.py", line 56, in single_nb_execution
    record_timing=False,
  File "C:\Users\Tomas\anaconda3.1\envs\test\lib\site-packages\nbclient\client.py", line 1204, in execute
    return NotebookClient(nb=nb, resources=resources, km=km, **kwargs).execute()
  File "C:\Users\Tomas\anaconda3.1\envs\test\lib\site-packages\nbclient\util.py", line 84, in wrapped
    return just_run(coro(*args, **kwargs))
  File "C:\Users\Tomas\anaconda3.1\envs\test\lib\site-packages\nbclient\util.py", line 62, in just_run
    return loop.run_until_complete(coro)
  File "C:\Users\Tomas\anaconda3.1\envs\test\lib\asyncio\base_events.py", line 587, in run_until_complete
    return future.result()
  File "C:\Users\Tomas\anaconda3.1\envs\test\lib\site-packages\nbclient\client.py", line 664, in async_execute
    cell, index, execution_count=self.code_cells_executed + 1
  File "C:\Users\Tomas\anaconda3.1\envs\test\lib\site-packages\nbclient\client.py", line 965, in async_execute_cell
    await self._check_raise_for_error(cell, cell_index, exec_reply)
  File "C:\Users\Tomas\anaconda3.1\envs\test\lib\site-packages\nbclient\client.py", line 862, in _check_raise_for_error
    raise CellExecutionError.from_cell_and_msg(cell, exec_reply_content)
nbclient.exceptions.CellExecutionError: An error occurred while executing the following cell:
------------------
from ipyleaflet import *
import json


#make the map
m = Map(center=(50,-120), zoom=6, basemap = basemaps.Esri.DeLorme)

#add the layers
with open('test.geojson') as f:
    data = json.load(f)

geo = GeoJSON(data=data,
              style = {
                'color': 'blue'
              })

m.add_layer(geo)

# #attempt at querying data from pg_featureserv API for bcfishpass

# import requests
# import json

# response_API = requests.get('https://features.hillcrestgeo.ca/bcfishpass/collections/bcfishpass.streams/items.json')
# print(response_API.status_code)

# parse = response_API.text
# gjson = json.loads(parse)

# geo1 = GeoJSON(data=gjson,
#               style = {
#                 'color': 'blue'
#               })

# m.add_layer(geo1)


m

------------------

[1;31m---------------------------------------------------------------------------[0m
[1;31mFileNotFoundError[0m                         Traceback (most recent call last)
[1;32m~\AppData\Local\Temp\ipykernel_15916\2907338158.py[0m in [0;36m<module>[1;34m[0m
[0;32m      7[0m [1;33m[0m[0m
[0;32m      8[0m [1;31m#add the layers[0m[1;33m[0m[1;33m[0m[1;33m[0m[0m
[1;32m----> 9[1;33m [1;32mwith[0m [0mopen[0m[1;33m([0m[1;34m'test.geojson'[0m[1;33m)[0m [1;32mas[0m [0mf[0m[1;33m:[0m[1;33m[0m[1;33m[0m[0m
[0m[0;32m     10[0m     [0mdata[0m [1;33m=[0m [0mjson[0m[1;33m.[0m[0mload[0m[1;33m([0m[0mf[0m[1;33m)[0m[1;33m[0m[1;33m[0m[0m
[0;32m     11[0m [1;33m[0m[0m

[1;31mFileNotFoundError[0m: [Errno 2] No such file or directory: 'test.geojson'
FileNotFoundError: [Errno 2] No such file or directory: 'test.geojson'

