Traceback (most recent call last):
  File "C:\Users\TMillaKoch\Anaconda3\envs\test\lib\site-packages\nbclient\client.py", line 780, in _async_poll_for_reply
    msg = await ensure_async(self.kc.shell_channel.get_msg(timeout=new_timeout))
  File "C:\Users\TMillaKoch\Anaconda3\envs\test\lib\site-packages\nbclient\util.py", line 97, in ensure_async
    result = await obj
  File "C:\Users\TMillaKoch\Anaconda3\envs\test\lib\site-packages\jupyter_client\channels.py", line 230, in get_msg
    raise Empty
_queue.Empty

During handling of the above exception, another exception occurred:

Traceback (most recent call last):
  File "C:\Users\TMillaKoch\Anaconda3\envs\test\lib\site-packages\jupyter_cache\executors\utils.py", line 56, in single_nb_execution
    record_timing=False,
  File "C:\Users\TMillaKoch\Anaconda3\envs\test\lib\site-packages\nbclient\client.py", line 1269, in execute
    return NotebookClient(nb=nb, resources=resources, km=km, **kwargs).execute()
  File "C:\Users\TMillaKoch\Anaconda3\envs\test\lib\site-packages\nbclient\util.py", line 85, in wrapped
    return just_run(coro(*args, **kwargs))
  File "C:\Users\TMillaKoch\Anaconda3\envs\test\lib\site-packages\nbclient\util.py", line 60, in just_run
    return loop.run_until_complete(coro)
  File "C:\Users\TMillaKoch\Anaconda3\envs\test\lib\asyncio\base_events.py", line 587, in run_until_complete
    return future.result()
  File "C:\Users\TMillaKoch\Anaconda3\envs\test\lib\site-packages\nbclient\client.py", line 708, in async_execute
    cell, index, execution_count=self.code_cells_executed + 1
  File "C:\Users\TMillaKoch\Anaconda3\envs\test\lib\site-packages\nbclient\client.py", line 1006, in async_execute_cell
    exec_reply = await self.task_poll_for_reply
  File "C:\Users\TMillaKoch\Anaconda3\envs\test\lib\site-packages\nbclient\client.py", line 804, in _async_poll_for_reply
    error_on_timeout_execute_reply = await self._async_handle_timeout(timeout, cell)
  File "C:\Users\TMillaKoch\Anaconda3\envs\test\lib\site-packages\nbclient\client.py", line 857, in _async_handle_timeout
    "Cell execution timed out", timeout, cell
nbclient.exceptions.CellTimeoutError: A cell timed out while it was being executed, after 30 seconds.
The message was: Cell execution timed out.
Here is a preview of the cell contents:
-------------------
['#configuring the app', '#useful resources include:', '#https://github.com/Coding-with-Adam/Dash-by-Plotly/blob/master/Other/Dash_Introduction/intro.py', '#https://dash-leaflet.herokuapp.com/', '#https://github.com/plotly/jupyter-dash/blob/master/notebooks/getting_started.ipynb']
...
['# ------------------------------------------------------------------------------', "if __name__ == '__main__':", '    app.run_server()', '    #app.run_server(debug=True, port = random.choice(range(2000, 10000)))', "    #mode = 'inline' for JD"]
-------------------

